<?xml version="1.0"?>
<robot xmlns:xacro="http://www.ros.org/wiki/xacro" >

    <!-- Specify some standard inertial calculations https://en.wikipedia.org/wiki/List_of_moments_of_inertia -->
    <!-- These make use of xacro's mathematical functionality -->

    <xacro:macro name="inertial_sphere" params="mass radius *origin">
        <inertial>
            <xacro:insert_block name="origin"/>
            <mass value="${mass}" />
            <inertia ixx="${(2/5) * mass * (radius*radius)}" ixy="0.0" ixz="0.0"
                    iyy="${(2/5) * mass * (radius*radius)}" iyz="0.0"
                    izz="${(2/5) * mass * (radius*radius)}" />
        </inertial>
    </xacro:macro>  


    <xacro:macro name="inertial_box" params="mass x y z *origin">
        <inertial>
            <xacro:insert_block name="origin"/>
            <mass value="${mass}" />
            <inertia ixx="${(1/12) * mass * (y*y+z*z)}" ixy="0.0" ixz="0.0"
                    iyy="${(1/12) * mass * (x*x+z*z)}" iyz="0.0"
                    izz="${(1/12) * mass * (x*x+y*y)}" />
        </inertial>
    </xacro:macro>


    <xacro:macro name="inertial_cylinder" params="mass length radius *origin">
        <inertial>
            <xacro:insert_block name="origin"/>
            <mass value="${mass}" />
            <inertia ixx="${(1/12) * mass * (3*radius*radius + length*length)}" ixy="0.0" ixz="0.0"
                    iyy="${(1/12) * mass * (3*radius*radius + length*length)}" iyz="0.0"
                    izz="${(1/2) * mass * (radius*radius)}" />
        </inertial>
    </xacro:macro>


<!--    MECANUM WHEEL MACRO-->

    <xacro:macro name="mecanum_wheel" params="scale xyz rpy joint_name child_link">
        <joint name="${joint_name}" type="continuous">
        <parent link="chassis"/>
        <child link="${child_link}"/>
        <origin xyz="${xyz}" rpy="${rpy}" />
        <axis xyz="0 1 0"/>
    </joint>

    <link name="${child_link}">

        <visual>
            <geometry>
                <mesh filename="file://$(find mecanum_robot)/description/meshes/mecanum_wheel_right.STL" scale="0.0015 0.0015 0.0015"/>
            </geometry>
            <material name="grey"/>
        </visual>

        <collision>
            <origin xyz="0 0 0" rpy="1.5708 0 0"/>
            <geometry>
                <cylinder radius="${scale * 51.3}" length="${scale * 49}"/>
<!--                <cylinder radius="0.144" length="0.13"/>-->
<!--                <cylinder radius="0.154" length="0.150"/>-->
            </geometry>
        </collision>
        <xacro:inertial_cylinder mass="0.1" length="${scale * 50}" radius="${scale * 51.3}">
            <origin xyz="0 0 0" rpy="0 0 0"/>
        </xacro:inertial_cylinder>
    </link>

        <gazebo reference="${child_link}">
        <material>Gazebo/Grey</material>
    </gazebo>
    </xacro:macro>



<!--    COLORS FOR GAZEBO-->


</robot>